Workbook

Sheet 电子书清单
A1: 序号 | B1: 书名 | C1: 副标题/版次 | D1: 类型 | E1: 出版年 | F1: 作者/编者(检索页显示) | G1: 所属丛书 | H1: DOI / ISBN | I1: 链接 | J1: 主题分类 | K1: 与骨科康复相关度
A2: 1 | B2: Orthopedic Rehabilitation | C2: Principles and Practice | D2: 教科书 | E2: 2023 | H2: 10.1007/978-3-031-32026-2 | I2: https://link.springer.com/book/10.1007/978-3-031-32026-2 | J2: 骨科康复总论 | K2: 高
A3: 2 | B3: Rehabilitation for Nerve Transfers of the Upper Extremity | C3: A Clinical Manual | D3: 图书 | E3: 2025 | H3: 10.1007/978-3-031-92008-0 | I3: https://link.springer.com/book/10.1007/978-3-031-92008-0 | J3: 手/上肢 | K3: 高
A4: 3 | B4: Anterior Cruciate Ligament Injuries Throughout the Life Span | D4: 图书 | E4: 2025 | H4: 10.1007/978-3-031-84501-7 | I4: https://link.springer.com/book/10.1007/978-3-031-84501-7 | J4: 膝/ACL | K4: 中
A5: 4 | B5: Video Atlas of Neuromusculoskeletal Ultrasound | D5: 图书 | E5: 2025 | H5: 10.1007/978-3-031-81037-4 | I5: https://link.springer.com/book/10.1007/978-3-031-81037-4 | J5: 影像/超声 | K5: 低
A6: 5 | B6: Telerehabilitation | D6: 图书 | E6: 2024 | G6: TELe-Health | H6: 10.1007/978-3-031-69080-8 | I6: https://link.springer.com/book/10.1007/978-3-031-69080-8 | J6: 康复技术/远程康复 | K6: 中
A7: 6 | B7: Textbook of Musculoskeletal Disorders | D7: 教科书 | E7: 2023 | H7: 10.1007/978-3-031-20987-1 | I7: https://link.springer.com/book/10.1007/978-3-031-20987-1 | J7: 骨科康复总论 | K7: 中
A8: 7 | B8: Handbook of Esports Medicine | C8: Clinical Aspects of Competitive Video Gaming (2nd ed.) | D8: 图书 | E8: 2026 | H8: ISBN 9783032369543 | I8: https://link.springer.com/book/9783032369543 | J8: 运动医学 | K8: 低
A9: 8 | B9: Knee Arthroscopy and Knee Preservation Surgery | D9: 参考工具书 | E9: 2024 | H9: 10.1007/978-3-031-29430-3 | I9: https://link.springer.com/book/10.1007/978-3-031-29430-3 | J9: 膝/ACL | K9: 中
A10: 9 | B10: Management and Rehabilitation of Spinal Cord Injuries | C10: (2nd ed.) | D10: 图书 | E10: 2022 | F10: Hyun-Yoon Ko | H10: 10.1007/978-981-19-0228-4 | I10: https://link.springer.com/book/10.1007/978-981-19-0228-4 | J10: 脊柱/脊髓 | K10: 高
A11: 10 | B11: Multidisciplinary Spine Tumor Management | C11: A Modern Approach | D11: 图书 | E11: 2025 | H11: 10.1007/978-3-032-07519-2 | I11: https://link.springer.com/book/10.1007/978-3-032-07519-2 | J11: 脊柱/脊髓 | K11: 低
A12: 11 | B12: Medical Robot Technology | D12: 图书 | E12: 2024 | F12: Jingang Jiang, Dianhao Wu, ... Xuesong Dai | G12: Advanced and Intelligent Manufacturing in China | H12: 10.1007/978-981-97-1484-1 | I12: https://link.springer.com/book/10.1007/978-981-97-1484-1 | J12: 康复技术/远程康复 | K12: 低
A13: 12 | B13: Advances in Total Hip Arthroplasty | D13: 图书 | E13: 2024 | H13: 10.1007/978-981-97-2461-1 | I13: https://link.springer.com/book/10.1007/978-981-97-2461-1 | J13: 关节置换 | K13: 中
A14: 13 | B14: One-Stage Septic Revision Arthroplasty | C14: Principles and Management | D14: 图书 | E14: 2024 | H14: 10.1007/978-3-031-59160-0 | I14: https://link.springer.com/book/10.1007/978-3-031-59160-0 | J14: 关节置换 | K14: 低
A15: 14 | B15: Contemporary and Global Perspectives in Physical Therapy | D15: 教科书 | E15: 2026 | H15: 10.1007/978-3-031-86558-9 | I15: https://link.springer.com/book/10.1007/978-3-031-86558-9 | J15: 骨科康复总论 | K15: 中
A16: 15 | B16: Critical Rehabilitation for Partial and Total Knee Arthroplasty | C16: Guidelines and Objective Testing to Allow Return to Physical Function, Recreational and Sports Activities | D16: 图书 | E16: 2022 | H16: 10.1007/978-3-030-87003-4 | I16: https://link.springer.com/book/10.1007/978-3-030-87003-4 | J16: 关节置换 | K16: 高
A17: 16 | B17: Low Back Ache | C17: A comprehensive guide to management | D17: 参考工具书 | E17: 2027 | H17: ISBN 9789819738762 | I17: https://link.springer.com/book/9789819738762 | J17: 脊柱/腰痛 | K17: 中
A18: 17 | B18: Arthroscopy and Endoscopy of the Shoulder | C18: Principle and Practice | D18: 图书 | E18: 2023 | H18: 10.1007/978-981-19-7884-5 | I18: https://link.springer.com/book/10.1007/978-981-19-7884-5 | J18: 肩/肘 | K18: 低
A19: 18 | B19: Endoscopy of the Spine | C19: Principle and Practice | D19: 图书 | E19: 2023 | H19: 10.1007/978-981-19-7761-9 | I19: https://link.springer.com/book/10.1007/978-981-19-7761-9 | J19: 脊柱/腰痛 | K19: 低
A20: 19 | B20: Low Back Ache | C20: A comprehensive guide to management | D20: 在线持续更新参考书 | E20: 2026 | H20: 10.1007/978-981-97-4087-1 | I20: https://link.springer.com/book/10.1007/978-981-97-4087-1 | J20: 脊柱/腰痛 | K20: 中
A21: 20 | B21: The Achilles Tendon | C21: Pathology, Treatment and Rehabilitation | D21: 图书 | E21: 2023 | H21: 10.1007/978-3-031-45594-0 | I21: https://link.springer.com/book/10.1007/978-3-031-45594-0 | J21: 足/踝 | K21: 高
A22: 21 | B22: Low Back Pain and Sciatica | C22: A New Pathogenetic Model and Treatment Principles | D22: 图书 | E22: 2025 | F22: Luigi Tesio | H22: 10.1007/978-3-031-78534-4 | I22: https://link.springer.com/book/10.1007/978-3-031-78534-4 | J22: 脊柱/腰痛 | K22: 中
A23: 22 | B23: Percutaneous and Minimally Invasive Foot Surgery | D23: 图书 | E23: 2023 | H23: 10.1007/978-3-030-98791-6 | I23: https://link.springer.com/book/10.1007/978-3-030-98791-6 | J23: 足/踝 | K23: 低
A24: 23 | B24: Textbook of Veterinary Orthopaedic Surgery | D24: 教科书 | E24: 2023 | F24: Hari Prasad Aithal, Amar Pal, ... Abhijit M Pawde | H24: 10.1007/978-981-99-2575-9 | I24: https://link.springer.com/book/10.1007/978-981-99-2575-9 | J24: 其他 | K24: 低
A25: 24 | B25: Rehabilitation After Limb Salvage Surgery | D25: 图书 | E25: 2021 | H25: 10.1007/978-3-030-66352-0 | I25: https://link.springer.com/book/10.1007/978-3-030-66352-0 | J25: 骨肿瘤/截肢 | K25: 高
A26: 25 | B26: Ligamentous Injuries of the Foot and Ankle | C26: Diagnosis, Management and Rehabilitation | D26: 图书 | E26: 2022 | H26: 10.1007/978-3-031-08682-3 | I26: https://link.springer.com/book/10.1007/978-3-031-08682-3 | J26: 足/踝 | K26: 高
A27: 26 | B27: Orthopedics for Physician Assistant and Nurse Practitioner Students | C27: An Introductory Guide | D27: 教科书 | E27: 2022 | F27: John A. Gracy | H27: 10.1007/978-3-031-04406-9 | I27: https://link.springer.com/book/10.1007/978-3-031-04406-9 | J27: 骨科康复总论 | K27: 低
A28: 27 | B28: Pediatric and Adult Hand Fractures | C28: A Clinical Guide to Management | D28: 图书 | E28: 2023 | H28: 10.1007/978-3-031-32072-9 | I28: https://link.springer.com/book/10.1007/978-3-031-32072-9 | J28: 手/上肢 | K28: 中
A29: 28 | B29: Knee Arthroscopy and Knee Preservation Surgery | D29: 在线持续更新参考书 | E29: 2023 | H29: 10.1007/978-3-030-82869-1 | I29: https://link.springer.com/book/10.1007/978-3-030-82869-1 | J29: 膝/ACL | K29: 中
A30: 29 | B30: Spondylolisthesis | C30: Diagnosis, Non-Surgical Management, and Surgical Techniques (2nd ed.) | D30: 图书 | E30: 2023 | H30: 10.1007/978-3-031-27253-0 | I30: https://link.springer.com/book/10.1007/978-3-031-27253-0 | J30: 脊柱/腰痛 | K30: 中
A31: 30 | B31: Atlas of Finger Reconstruction | C31: Techniques and Cases | D31: 图书 | E31: 2023 | F31: Jian Lin, Jianli Wang, ... Tianhao Zhang | H31: 10.1007/978-981-19-9612-2 | I31: https://link.springer.com/book/10.1007/978-981-19-9612-2 | J31: 手/上肢 | K31: 低
A32: 31 | B32: Neurosurgery for Spasticity | C32: A Practical Guide for Treating Children and Adults (2nd ed.) | D32: 图书 | E32: 2022 | F32: Marc Sindou, Manon Duraffourg, George Georgoulis | H32: 10.1007/978-3-030-92717-2 | I32: https://link.springer.com/book/10.1007/978-3-030-92717-2 | J32: 神经/痉挛 | K32: 低
A33: 32 | B33: Fundamentals of the Shoulder | D33: 图书 | E33: 2022 | H33: 10.1007/978-3-030-94702-6 | I33: https://link.springer.com/book/10.1007/978-3-030-94702-6 | J33: 肩/肘 | K33: 中
A34: 33 | B34: Rarer Arthropathies | D34: 图书 | E34: 2022 | G34: Rare Diseases of the Immune System | H34: 10.1007/978-3-031-05002-2 | I34: https://link.springer.com/book/10.1007/978-3-031-05002-2 | J34: 风湿/血友病 | K34: 低
A35: 34 | B35: Advances in Hemophilia Treatment | C35: From Genetics to Joint Health | D35: 图书 | E35: 2022 | H35: 10.1007/978-3-030-93990-8 | I35: https://link.springer.com/book/10.1007/978-3-030-93990-8 | J35: 风湿/血友病 | K35: 低
A36: 35 | B36: Orthopedic Care of Patients with Cerebral Palsy | C36: A Clinical Guide to Evaluation and Management across the Lifespan | D36: 图书 | E36: 2020 | H36: 10.1007/978-3-030-46574-2 | I36: https://link.springer.com/book/10.1007/978-3-030-46574-2 | J36: 儿科 | K36: 中
A37: 36 | B37: Endoscopy of the Hip and Knee | C37: Principle and Practice | D37: 图书 | E37: 2021 | H37: 10.1007/978-981-16-3488-8 | I37: https://link.springer.com/book/10.1007/978-981-16-3488-8 | J37: 髋 | K37: 低
A38: 37 | B38: Geriatric Hip Fractures | C38: A Practical Approach | D38: 图书 | E38: 2021 | H38: 10.1007/978-3-030-78969-5 | I38: https://link.springer.com/book/10.1007/978-3-030-78969-5 | J38: 创伤/骨折 | K38: 中
A39: 38 | B39: The Failed Rotator Cuff | C39: Diagnosis and Management | D39: 图书 | E39: 2021 | H39: 10.1007/978-3-030-79481-1 | I39: https://link.springer.com/book/10.1007/978-3-030-79481-1 | J39: 肩/肘 | K39: 中
A40: 39 | B40: Return-to-Play after Lower Limb Muscle Injury in Football | C40: The Italian Consensus Conference Guidelines | D40: 图书 | E40: 2022 | F40: Gian Nicola Bisciotti, Alessandro Corsini, Piero Volpi | H40: 10.1007/978-3-030-84950-4 | I40: https://link.springer.com/book/10.1007/978-3-030-84950-4 | J40: 运动医学 | K40: 高
...

Sheet 统计汇总
A1: Springer Nature Link 检索："Orthopedic Rehabilitation"，内容类型=Book，按相关度排序，共 109 条（检索日期 2026-10-08）
A2: 注：主题分类与相关度为根据书名/简介人工判断；作者栏仅含检索结果页显示的作者，编著类图书在页面上不显示编者故留空。
A4: 按相关度
A5: 类别 | B5: 数量
A6: 高 | B6: =COUNTIF(电子书清单!$K$2:$K$110,A6) -> 21
A7: 中 | B7: =COUNTIF(电子书清单!$K$2:$K$110,A7) -> 43
A8: 低 | B8: =COUNTIF(电子书清单!$K$2:$K$110,A8) -> 45
A9: 合计 | B9: =SUM(B6:B8) -> 109
A11: 按类型
A12: 类别 | B12: 数量
A13: 图书 | B13: =COUNTIF(电子书清单!$D$2:$D$110,A13) -> 99
A14: 教科书 | B14: =COUNTIF(电子书清单!$D$2:$D$110,A14) -> 6
A15: 参考工具书 | B15: =COUNTIF(电子书清单!$D$2:$D$110,A15) -> 2
A16: 在线持续更新参考书 | B16: =COUNTIF(电子书清单!$D$2:$D$110,A16) -> 2
A17: 合计 | B17: =SUM(B13:B16) -> 109
A19: 按主题
A20: 类别 | B20: 数量
A21: 骨科康复总论 | B21: =COUNTIF(电子书清单!$J$2:$J$110,A21) -> 11
A22: 手/上肢 | B22: =COUNTIF(电子书清单!$J$2:$J$110,A22) -> 7
A23: 膝/ACL | B23: =COUNTIF(电子书清单!$J$2:$J$110,A23) -> 13
A24: 影像/超声 | B24: =COUNTIF(电子书清单!$J$2:$J$110,A24) -> 2
A25: 康复技术/远程康复 | B25: =COUNTIF(电子书清单!$J$2:$J$110,A25) -> 2
A26: 运动医学 | B26: =COUNTIF(电子书清单!$J$2:$J$110,A26) -> 9
A27: 脊柱/脊髓 | B27: =COUNTIF(电子书清单!$J$2:$J$110,A27) -> 3
A28: 关节置换 | B28: =COUNTIF(电子书清单!$J$2:$J$110,A28) -> 8
A29: 脊柱/腰痛 | B29: =COUNTIF(电子书清单!$J$2:$J$110,A29) -> 9
A30: 肩/肘 | B30: =COUNTIF(电子书清单!$J$2:$J$110,A30) -> 11
A31: 足/踝 | B31: =COUNTIF(电子书清单!$J$2:$J$110,A31) -> 6
A32: 其他 | B32: =COUNTIF(电子书清单!$J$2:$J$110,A32) -> 3
... A38: 创伤/骨折 | B38: =COUNTIF(电子书清单!$J$2:$J$110,A38) -> 6
A39: 合计 | B39: =SUM(B21:B38) -> 109
A41: 按出版年代
A42: 年代 | B42: 数量
A43: 2000–2009 | B43: =COUNTIFS(电子书清单!$E$2:$E$110,">=2000",电子书清单!$E$2:$E$110,"<=2009") -> 9
A44: 2010–2019 | B44: =COUNTIFS(电子书清单!$E$2:$E$110,">=2010",电子书清单!$E$2:$E$110,"<=2019") -> 43
A45: 2020–2027 | B45: =COUNTIFS(电子书清单!$E$2:$E$110,">=2020",电子书清单!$E$2:$E$110,"<=2027") -> 57
