Workbook

Sheet 英文出版社
A1: 序号 | B1: 出版社 | C1: 子品牌 | D1: 书名 | E1: 副标题 | F1: 中文书名（译） | G1: 版次 | H1: 出版年 | I1: 作者/编者 | J1: 纸书 ISBN | K1: 电子书 ISBN | L1: 电子版 | M1: 在线资源/视频 | N1: 主题分类 | O1: 相关度 | P1: 链接 | Q1: 备注
A2: 1 | B2: Cambridge University Press | C2: Cambridge University Press | D2: Sports Medicine for the Emergency Physician | E2: A Practical Handbook | F2: 急诊医师运动医学实用手册 | G2: 1st | H2: 2016 | I2: Anna L. Waterbrook (ed) | J2: 9781107449886 | L2: 有 | N2: 运动康复 | O2: 低 | P2: https://www.cambridge.org/core/search?q=9781107449886 | Q2: 偏急诊处置，康复内容少；CUP 在本领域几乎无专门康复书
A3: 2 | B3: Elsevier | C3: Elsevier | D3: Clinical Orthopaedic Rehabilitation | E3: A Team Approach | F3: 临床骨科康复：团队协作方法（第5版） | G3: 5th | H3: 2027 | I3: Charles E. Giangarra, Robert C. Manske, David Rupp (eds.) | J3: 9780443286315 | K3: 9780443286322 | L3: 有 | N3: 骨科康复总论 | O3: 高 | P3: https://shop.elsevier.com/books/clinical-orthopaedic-rehabilitation/giangarra/978-0-443-28631-5 | Q3: 尚未出版（官网预告 2027-07），可列为预订；另一 eBook ISBN 9780443286339
A4: 3 | B4: Elsevier | C4: Saunders | D4: Magee's Orthopedic Physical Assessment | F4: Magee 骨科物理评估 | G4: 8th | H4: 2026 | I4: Robert C. Manske, David J. Magee | J4: 9780443128646 | K4: 9780443128165 | L4: 有 | M4: 随书增强电子书，含特殊诊断试验在线视频 | N4: 评估 | O4: 高 | P4: https://shop.elsevier.com/books/magee-s-orthopedic-physical-assessment/manske/978-0-443-12864-6 | Q4: 最新版；官网日期 2026-04，部分区域站为 2026-07；2026 Doody's Core Title
A5: 4 | B5: Elsevier | C5: Elsevier | D5: Orthopaedic Physical Therapy Secrets | F5: 骨科物理治疗精要（Secrets 系列） | G5: 4th | H5: 2024 | I5: Jeffrey D. Placzek, David A. Boyce (eds.) | J5: 9780323846578 | K5: 9780323837354 | L5: 有 | N5: 骨科康复总论 | O5: 高 | P5: https://shop.elsevier.com/books/orthopaedic-physical-therapy-secrets/placzek/978-0-323-84657-8 | Q5: 官网日期 2023-12-26，零售 2024-03；问答体
A6: 5 | B6: Elsevier | C6: Elsevier | D6: Grieve's Modern Musculoskeletal Physiotherapy | F6: Grieve 现代肌肉骨骼物理治疗 | G6: 5th | H6: 2024 | I6: Deborah Falla, Chad E. Cook, Jeremy Lewis, Christopher McCarthy, Michele Sterling (eds.) | J6: 9780702080890 | K6: 9780702080906 | L6: 有 | N6: 骨科康复总论 | O6: 高 | P6: https://shop.elsevier.com/books/grieves-modern-musculoskeletal-physiotherapy/falla/978-0-7020-8089-0 | Q6: 前一版第4版（Jull 等，2015，ISBN 9780702051524）
A7: 6 | B7: Elsevier | C7: Elsevier | D7: Petty's Musculoskeletal Examination and Assessment | E7: A Handbook for Therapists | F7: Petty 肌肉骨骼检查与评估：治疗师手册 | G7: 6th | H7: 2023 | I7: Dionne Ryder, Kieran Barnard (eds.) | J7: 9780323874717 | K7: 9780323874724 | L7: 有 | N7: 评估 | O7: 高 | P7: https://shop.elsevier.com/books/pettys-musculoskeletal-examination-and-assessment/ryder/978-0-323-87471-7 | Q7: 可与下一条组成两卷套装 ISBN 9780323849562
A8: 7 | B8: Elsevier | C8: Elsevier | D8: Petty's Principles of Musculoskeletal Treatment and Management | E8: A Handbook for Therapists | F8: Petty 肌肉骨骼治疗与管理原则：治疗师手册 | G8: 4th | H8: 2023 | I8: Kieran Barnard, Dionne Ryder (eds.) | J8: 9780323872287 | K8: 9780323872324 | L8: 有 | N8: 手法治疗 | O8: 高 | P8: https://shop.elsevier.com/books/pettys-principles-of-musculoskeletal-treatment-and-management/barnard/978-0-323-87228-7 | Q8: eBook ISBN 取自官网URL，待核实
A9: 8 | B9: Elsevier | C9: Elsevier | D9: Fundamental Orthopedic Management for the Physical Therapist Assistant | F9: 物理治疗师助理骨科管理基础 | G9: 5th | H9: 2022 | I9: Robert C. Manske (ed.) | J9: 9780323661713 | K9: 9780323661720 | L9: 有 | M9: Evolve 学习资源（待核实具体内容） | N9: 骨科康复总论 | O9: 高 | P9: https://www.us.elsevierhealth.com/fundamental-orthopedic-management-for-the-physical-therapist-assistant-9780323661713.html | Q9: 官网标2021-10，图书馆记录2022；另一 eText ISBN 9780323661737
A10: 9 | B10: Elsevier | C10: Elsevier | D10: Netter's Orthopaedic Clinical Examination | E10: An Evidence-Based Approach | F10: 奈特骨科临床检查：循证方法 | G10: 4th | H10: 2021 | I10: Joshua A. Cleland, Shane Koppenhaver, Jonathan Su | J10: 9780323695336 | K10: 9780323695343 | L10: 有 | M10: 随书电子书（是否含视频待核实） | N10: 评估 | O10: 高 | P10: https://www.us.elsevierhealth.com/netters-orthopaedic-clinical-examination-9780323695336.html | Q10: 官网 2021-03，图书馆记录 2022；另有 ISBN 9780323695350（版本形式待核实）
A11: 10 | B11: Elsevier | C11: Saunders | D11: Orthopedic Physical Assessment | F11: 骨科物理评估 | G11: 7th | H11: 2020 | I11: David J. Magee, Robert C. Manske | J11: 9780323522991 | K11: 9780323672566 | L11: 有 | M11: 随书增强电子书，含特殊检查视频 | N11: 评估 | O11: 高 | P11: https://shop.elsevier.com/books/orthopedic-physical-assessment/magee/978-0-323-52299-1 | Q11: 另有精装 ISBN 9780323749510、eBook 9780323550697；已被第8版取代
A12: 11 | B12: Elsevier | C12: Elsevier | D12: Rehabilitation of the Hand and Upper Extremity | E12: 2-Volume Set | F12: 手与上肢康复（两卷本） | G12: 7th | H12: 2020 | I12: Terri M. Skirven, A. Lee Osterman, Jane Fedorczyk, Peter C. Amadio, Sheri B. Feldscher, Eon Kyu Shin | J12: 9780323509138 | L12: 有 | M12: 随书增强电子书；大量视频库（神经损伤、手与上肢移植、手术与治疗管理） | N12: 手与上肢 | O12: 高 | P12: https://shop.elsevier.com/books/rehabilitation-of-the-hand-and-upper-extremity-2-volume-set/skirven/978-0-323-50913-8 | Q12: 手治疗领域权威参考书；部分区域站使用 ISBN 9780323547161
A13: 12 | B13: Elsevier | C13: Mosby | D13: Cooper's Fundamentals of Hand Therapy | E13: Clinical Reasoning and Treatment Guidelines for Common Diagnoses of the Upper Extremity | F13: Cooper 手治疗基础：上肢常见诊断的临床推理与治疗指南 | G13: 3rd | H13: 2020 | I13: Christine M. Wietlisbach (ed.) | J13: 9780323524797 | K13: 9780323550123 | L13: 有 | N13: 手与上肢 | O13: 高 | P13: https://www.elsevier.com/books/coopers-fundamentals-of-hand-therapy/wietlisbach/978-0-323-52479-7 | Q13: 官网另列 ISBN 9780443111389 为即将出版的新版（待核实）
A14: 13 | B14: Elsevier | C14: Elsevier Australia | D14: The Mulligan Concept of Manual Therapy | E14: Textbook of Techniques | F14: Mulligan 手法治疗理念：技术教程 | G14: 2nd | H14: 2019 | I14: Wayne Hing, Toby Hall, Brian Mulligan | J14: 9780729542821 | L14: 有 | N14: 手法治疗 | O14: 高 | P14: https://shop.elsevier.com/books/the-mulligan-concept-of-manual-therapy/hing/978-0-7295-4282-1 | Q14: 第1版 ISBN 9780729581592
A15: 14 | B15: Elsevier | C15: Elsevier | D15: Clinical Orthopaedic Rehabilitation | E15: A Team Approach | F15: 临床骨科康复：团队协作方法 | G15: 4th | H15: 2018 | I15: Charles E. Giangarra, Robert C. Manske (eds.) | J15: 9780323393706 | K15: 9780323477895 | L15: 有 | M15: 随书增强电子书（Expert Consult/eBook），具体视频内容待核实 | N15: 骨科康复总论 | O15: 高 | P15: https://shop.elsevier.com/books/clinical-orthopaedic-rehabilitation/giangarra/978-0-323-39370-6 | Q15: Brotzman 经典教材的后继版本；版权年2018，官网页面日期不一（2017/2020）；第5版已预告（2027）
A16: 15 | B16: Elsevier | C16: Saunders | D16: Pathology and Intervention in Musculoskeletal Rehabilitation | F16: 肌肉骨骼康复中的病理与干预 | G16: 2nd | H16: 2016 | I16: David J. Magee, James E. Zachazewski, William S. Quillen, Robert C. Manske | J16: 9780323310727 | K16: 9780323310734 | L16: 有 | N16: 骨科康复总论 | O16: 高 | P16: https://www.us.elsevierhealth.com/pathology-and-intervention-in-musculoskeletal-rehabilitation-9780323310727.html | Q16: Magee 肌骨康复系列；出版2015-11/版权2016；eBook ISBN 另见 9780323310765，待核实
A17: 16 | B17: Elsevier | C17: Churchill Livingstone | D17: Hand and Upper Extremity Rehabilitation | E17: A Practical Guide | F17: 手与上肢康复实用指南 | G17: 4th | H17: 2016 | I17: Rebecca Saunders, Romina Astifidis, Susan L. Burke, James Higgins, Michael A. McClinton | J17: 9781455756476 | K17: 9781455756490 | L17: 有 | N17: 手与上肢 | O17: 高 | P17: https://www.us.elsevierhealth.com/hand-and-upper-extremity-rehabilitation-9781455756476.html | Q17: 部分来源出版年为2015
A18: 17 | B18: Elsevier | C18: Saunders | D18: Orthopaedic Rehabilitation of the Athlete | E18: Getting Back in the Game | F18: 运动员骨科康复：重返赛场 | G18: 1st | H18: 2015 | I18: Bruce Reider, George J. Davies, Matthew T. Provencher (eds.) | J18: 9781455727803 | K18: 9781455737437 | L18: 有 | N18: 运动康复 | O18: 高 | P18: https://eld.bl.uk/catalog/018086804 | Q18: 约1600页，覆盖颈椎至足部的运动损伤及术后康复方案与运动处方；官网页未直接核实
A19: 18 | B19: Elsevier | C19: Churchill Livingstone | D19: Manual Therapy for Musculoskeletal Pain Syndromes | E19: An Evidence- and Clinical-Informed Approach | F19: 肌肉骨骼疼痛综合征的手法治疗：循证与临床指导方法 | G19: 1st | H19: 2015 | I19: César Fernández-de-las-Peñas, Joshua Cleland, Jan Dommerholt (eds.) | J19: 9780702055768 | K19: 9780702055775 | L19: 有 | N19: 手法治疗 | O19: 高 | P19: https://tienda.elsevier.com/books/manual-therapy-for-musculoskeletal-pain-syndromes/fernandez-de-las-penas/978-0-7020-5576-8 | Q19: 出版2015-04，部分图书馆记录为2016；按部位（肩、髋、肘、膝、腕手、踝足）分章
A20: 19 | B20: Elsevier | C20: Churchill Livingstone | D20: Maitland's Peripheral Manipulation | E20: Management of Neuromusculoskeletal Disorders - Volume 2 | F20: Maitland 外周关节手法治疗（神经肌肉骨骼疾病管理 第2卷） | G20: 5th | H20: 2014 | I20: Elly Hengeveld, Kevin Banks (eds.) | J20: 9780702040672 | L20: 有 | N20: 手法治疗 | O20: 高 | P20: https://www.us.elsevierhealth.com/maitlands-peripheral-manipulation-9780702040672.html | Q20: 2015年前出版但仍为最新版
A21: 20 | B21: Elsevier | C21: Mosby | D21: Rehabilitation for the Postsurgical Orthopedic Patient | F21: 骨科术后患者的康复 | G21: 3rd | H21: 2013 | I21: Lisa Maxey, Jim Magnusson (eds.) | J21: 9780323077477 | K21: 9780323291392 | L21: 有 | N21: 骨科康复总论 | O21: 高 | P21: https://www.eu.elsevierhealth.com/rehabilitation-for-the-postsurgical-orthopedic-patient-9780323077477.html | Q21: 未见第4版，3版仍为最新版；2015年前出版
A22: 21 | B22: Elsevier | C22: Churchill Livingstone | D22: Maitland's Vertebral Manipulation | E22: Management of Neuromusculoskeletal Disorders - Volume 1 | F22: Maitland 脊柱手法治疗（神经肌肉骨骼疾病管理 第1卷） | G22: 8th | H22: 2013 | I22: Elly Hengeveld, Kevin Banks (eds.) | J22: 9780702040665 | L22: 有 | N22: 脊柱 | O22: 高 | P22: https://www.us.elsevierhealth.com/maitlands-vertebral-manipulation-9780702040665.html | Q22: 2015年前出版但仍为最新版；区域站另见 ISBN 9780702054587（疑为 eBook）
A23: 22 | B23: Elsevier | C23: Saunders | D23: Physical Rehabilitation of the Injured Athlete | F23: 受伤运动员的物理康复 | G23: 4th | H23: 2012 | I23: James R. Andrews, Gary L. Harrelson, Kevin E. Wilk | J23: 9781437724110 | K23: 9781455737444 | L23: 有 | M23: Expert Consult 印刷+在线版 | N23: 运动康复 | O23: 高 | P23: https://shop.elsevier.com/books/physical-rehabilitation-of-the-injured-athlete/andrews/978-1-4377-2411-0 | Q23: 未见更新版本，2015年前出版
A24: 23 | B24: Elsevier | C24: Mosby | D24: Clinical Orthopaedic Rehabilitation | E24: An Evidence-Based Approach | F24: 临床骨科康复学：循证方法 | G24: 3rd | H24: 2011 | I24: S. Brent Brotzman, Robert C. Manske (eds.) | J24: 9780323055901 | K24: 9780323081252 | L24: 有 | M24: Expert Consult 在线版，含康复技术视频 | N24: 骨科康复总论 | O24: 高 | P24: https://shop.elsevier.com/books/clinical-orthopaedic-rehabilitation-an-evidence-based-approach/brotzman/978-0-323-05590-1 | Q24: 经典 Brotzman 版，已被上面 Team Approach 版取代，2015年前出版；另见 eText ISBN 9780323296762
A25: 24 | B25: Elsevier | C25: Mosby | D25: Postsurgical Rehabilitation Guidelines for the Orthopedic Clinician | F25: 骨科临床医师术后康复指南 | G25: 1st | H25: 2006 | I25: Hospital for Special Surgery Rehabilitation Department; JeMe Cioppa-Mosca, Janet B. Cahill, Carmen Young Tucker (eds.) | J25: 9780323032001 | K25: 9780323059008 | L25: 有 | M25: 印刷版附 DVD（60余分钟治疗性运动视频） | N25: 关节置换 | O25: 高 | P25: https://www.us.elsevierhealth.com/postsurgical-rehabilitation-guidelines-for-the-orthopedic-clinician-9780323059008.html | Q25: 出版较早（2006），HSS 分期康复方案，含全髋/全膝/全肩置换
A26: 25 | B26: Elsevier | C26: Elsevier | D26: Neumann's Kinesiology of the Musculoskeletal System | F26: Neumann 肌肉骨骼系统运动学 | G26: 4th | H26: 2024 | I26: Donald A. Neumann | J26: 9780323718592 | K26: 9780323831475 | L26: 有 | M26: 随书增强电子书，含解剖与运动学原理视频 | N26: 其他 | O26: 中 | P26: https://www.us.elsevierhealth.com/neumanns-kinesiology-of-the-musculoskeletal-system-9780323718592.html | Q26: 康复基础教材；出版2024-05，版权年2025
A27: 26 | B27: Elsevier | C27: Elsevier | D27: Daniels and Worthingham's Muscle Testing | E27: Techniques of Manual Muscle and Physical Performance Testing | F27: Daniels-Worthingham 肌肉测试：徒手肌力与体能测试技术 | G27: 11th | H27: 2024 | I27: Dale Avers, Donovan J. Lott, Marybeth Brown | J27: 9780323824200 | L27: 有 | M27: 随书电子书 | N27: 评估 | O27: 中 | P27: https://www.us.elsevierhealth.com/daniels-and-worthinghams-muscle-testing-9780323824200.html | Q27: 通用康复评估工具书，非骨科专用
A28: 27 | B28: Elsevier | C28: Elsevier | D28: Joint Range of Motion and Muscle Length Testing | F28: 关节活动度与肌肉长度测量 | G28: 4th | H28: 2023 | I28: Nancy Berryman Reese, William D. Bandy | J28: 9780323831871 | K28: 9780323831901 | L28: 有 | M28: 随书电子书 | N28: 评估 | O28: 中 | P28: https://shop.elsevier.com/books/joint-range-of-motion-and-muscle-length-testing/reese/978-0-323-83187-1 | Q28: 另一 eText ISBN 9780323831888，待核实
A29: 28 | B29: Elsevier | C29: Elsevier Australia | D29: Kinetic Control | E29: The Management of Uncontrolled Movement (Revised Edition) | F29: 动作控制：失控运动的管理（修订版） | G29: Revised ed. | H29: 2019 | I29: Mark Comerford, Sarah Mottram | J29: 9780729543262 | L29: 有 | N29: 手法治疗 | O29: 中 | P29: https://www.asia.elsevierhealth.com/kinetic-control-revised-edition-9780729543262.html | Q29: 运动控制/动作再训练；原版2012（ISBN 9780729541671）；topic 亦可归运动康复
A30: 29 | B30: Elsevier | C30: Churchill Livingstone | D30: Spinal Control: The Rehabilitation of Back Pain | E30: State of the Art and Science | F30: 脊柱控制：腰背痛康复的前沿与科学 | G30: 1st | H30: 2013 | I30: Paul W. Hodges, Jacek Cholewicki, Jaap H. van Dieën (eds.) | J30: 9780702043567 | K30: 9780702054549 | L30: 有 | N30: 脊柱 | O30: 中 | P30: https://www.uk.elsevierhealth.com/spinal-control-the-rehabilitation-of-back-pain-9780702043567.html | Q30: 偏科研；英国站显示按需印刷
A31: 30 | B31: Elsevier | C31: Saunders | D31: Athletic and Sport Issues in Musculoskeletal Rehabilitation | F31: 肌肉骨骼康复中的运动员与运动问题 | G31: 1st | H31: 2011 | I31: David J. Magee, Robert C. Manske, James E. Zachazewski, William S. Quillen | L31: 有 | N31: 运动康复 | O31: 中 | P31: https://www.us.elsevierhealth.com/athletic-and-sport-issues-in-musculoskeletal-rehabilitation-9781437715729.html | Q31: Magee 肌骨康复系列；官网URL含9781437715729（疑为eBook），印刷版ISBN未核实；2015年前出版
A32: 31 | B32: Elsevier | C32: Mosby | D32: Movement System Impairment Syndromes of the Extremities, Cervical and Thoracic Spines | F32: 四肢、颈椎及胸椎的运动系统损伤综合征 | G32: 1st | H32: 2011 | I32: Shirley Sahrmann and associates | J32: 9780323053426 | K32: 9780323083782 | L32: 有 | M32: Evolve 配套网站，含检查与操作视频 | N32: 评估 | O32: 中 | P32: https://www.elsevier.com/books/movement-system-impairment-syndromes-of-the-extremities-cervical-and-thoracic-spines/major/978-0-323-05342-6 | Q32: Sahrmann 第二部专著，配合 Diagnosis and Treatment of Movement Impairment Syndromes 使用；2015年前出版
A33: 32 | B33: F.A. Davis | D33: Therapeutic Exercise | E33: Foundations and Techniques | F33: 治疗性运动：基础与技术（第8版） | G33: 8th | H33: 2023 | I33: Carolyn Kisner; Lynn Allen Colby; John Borstad | J33: 9781719640473 | K33: 9781719649476 | L33: 有 | M33: F.A. Davis 在线资源（凭书内访问码）：治疗性运动视频库、6 个 Immersive Cases 多媒体病例 | N33: 骨科康复总论 | O33: 高 | Q33: 版权日期 2022-12，多数书目著录 2023；平台名称（DavisPlus/Davis Advantage）未核实
A34: 33 | B34: F.A. Davis | D34: Examination of Orthopedic & Athletic Injuries | F34: 骨科与运动损伤检查（第5版） | G34: 5th | H34: 2023 | I34: Chad Starkey; Blaine C. Long; Julie M. Cavallario | J34: 9780803690158 | K34: 9781719650076 | L34: 有 | M34: 在线资源（访问码）：关节活动度动画、各章复习题 | N34: 评估 | O34: 高 | Q34: 约 1040 页
A35: 34 | B35: F.A. Davis | D35: Orthopedic Interventions for the Physical Therapist Assistant | F35: 物理治疗师助理骨科干预 | G35: 1st | H35: 2020 | I35: Maureen Raffensperger | J35: 9780803643710 | K35: 9780803699526 | L35: 有 | N35: 骨科康复总论 | O35: 高 | Q35: 449 页；按肩、肘、腕手、脊柱、骨盆髋、膝、踝足分章；部分零售商标 2019
A36: 35 | B36: F.A. Davis | D36: Orthopaedic Manual Physical Therapy | E36: From Art to Evidence | F36: 骨科手法物理治疗：从艺术到证据 | G36: 1st | H36: 2015 | I36: Christopher H. Wise | J36: 9780803614970 | K36: 9780803645172 | L36: 有 | N36: 手法治疗 | O36: 高 | Q36: 936 页；电子 ISBN 来自书店 eText 列表
A37: 36 | B37: F.A. Davis | D37: Norkin & White's Measurement of Joint Motion | E37: A Guide to Goniometry | F37: Norkin & White 关节活动测量：量角法指南（第6版） | G37: 6th | H37: 2025 | I37: D. Joyce White | J37: 9781719642415 | K37: 9781719654852 | L37: 有 | N37: 评估 | O37: 中 | Q37: 2025年12月出版；PDF 版 ISBN 9781719642422；第5版（2016）由 Norkin & White 合著
A38: 37 | B38: F.A. Davis | D38: Ortho Notes | E38: Clinical Examination Pocket Guide | F38: 骨科笔记：临床检查袖珍指南（第5版） | G38: 5th | H38: 2024 | I38: Dawn Gulick | J38: 9781719648622 | L38: 未知 | N38: 评估 | O38: 中 | Q38: 第5版 ISBN/年份仅单一书商来源（2024/5），需核实；第4版 2018, ISBN 9780803666573
A39: 38 | B39: F.A. Davis | D39: Orthopedic Taping, Wrapping, Bracing, and Padding | F39: 骨科贴扎、包扎、支具与护垫（第4版） | G39: 4th | H39: 2021 | I39: Joel W. Beam | J39: 9781719640671 | K39: 9781719645539 | L39: 有 | N39: 运动康复 | O39: 中
A40: 39 | B40: Human Kinetics | D40: Therapeutic Interventions for Musculoskeletal Conditions | F40: 肌肉骨骼疾病的治疗性干预 | G40: 1st | H40: 2027 | I40: Craig R. Denegar; Grant E. Norte; Neal R. Glaviano | J40: 9781718230934 | K40: 9781718230941 | L40: 有 | M40: HKPropel 在线视频/资源 | N40: 骨科康复总论 | O40: 高 | P40: https://us.humankinetics.com/products/therapeutic-interventions-for-musculoskeletal-conditions-with-hkpropel-online-video | Q40: 官网标 ©2027，368 页，可能为新书/预售；整合物理因子、手法与治疗性运动的多模式方案
...

Sheet 中文出版社
A1: 序号 | B1: 出版社 | C1: 书名 | D1: 版次 | E1: 出版年 | F1: 主编/著者 | G1: 译者 | H1: 原创/译著 | I1: 原书名 | J1: 原版出版社 | K1: ISBN | L1: 主题分类 | M1: 相关度 | N1: 电子版 | O1: 链接
A2: 1 | B2: 上海交通大学出版社 | C2: 骨科疾病处理与康复治疗 | E2: 2023 | F2: 孟虎 等主编 | H2: 原创 | K2: 978-7-313-24053-8 | L2: 骨科康复总论 | M2: 中 | N2: 未知 | O2: https://wyutsg.wuyiu.edu.cn/mspace/searchDetailLocal/m82e8999ce9a845eaf40f14ad495ee365
A3: 2 | B3: 中国协和医科大学出版社 | C3: 肌骨复健实践指南：运动损伤与慢性疼痛 | E3: 2025 | F3: 金小斌 主编 | H3: 原创 | K3: 978-7-5679-2465-9 | L3: 运动康复 | M3: 高 | N3: 未知 | O3: https://lib.zy91.com/opac/book/40536
A4: 3 | B4: 中国协和医科大学出版社 | C4: 中国康复医学报告（2022） | E4: 2024 | F4: 王辰 主编 | H4: 原创 | K4: 978-7-5679-2370-6 | L4: 其他 | M4: 低 | N4: 未知 | O4: https://lib.zy91.com/opac/book/38463
A5: 4 | B5: 人民体育出版社 | C5: 体育中的运动治疗与康复 | E5: 2022 | F5: 王博源 著 | H5: 原创 | K5: 978-7-5009-6204-5 | L5: 运动康复 | M5: 中 | N5: 未知 | O5: https://libsys.dlnu.edu.cn/mspace/searchDetailLocal/md0e80afb9fd6132d29398db1f660b8e5
A6: 5 | B6: 人民体育出版社 | C6: 运动康复消疼痛：不开刀 不用药 | E6: 2018 | F6: 矫玮，钱菁华 | H6: 原创 | L6: 运动康复 | M6: 中 | N6: 未知 | O6: https://www.bsu.edu.cn/btrw/9795f755168147789a92caa846f43198.htm
A7: 6 | B7: 人民体育出版社 | C7: 运动康复生物力学 | D7: 第2版 | E7: 2015 | F7: 钱竞光，宋雅伟 主编 | H7: 原创 | L7: 运动康复 | M7: 中 | N7: 未知 | O7: https://book.douban.com/subject/30970420/
A8: 7 | B8: 人民军医出版社 | C8: 骨科物理康复治疗学 | D8: 第4版 | E8: 2017 | F8: (美) Robert A. Donatelli, Michael J. Wooden 原著 | G8: 周谋望, 刘楠, 杨延砚 主译 | H8: 译著 | I8: Orthopaedic Physical Therapy (4th ed.) | J8: Elsevier (Churchill Livingstone) | K8: 978-7-5091-9071-5 | L8: 骨科康复总论 | M8: 高 | N8: 未知 | O8: https://baike.baidu.com/item/%E9%AA%A8%E7%A7%91%E7%89%A9%E7%90%86%E5%BA%B7%E5%A4%8D%E6%B2%BB%E7%96%97%E5%AD%A6%E7%AC%AC4%E7%89%88/22168212
A9: 8 | B9: 人民军医出版社 | C9: 骨科术后康复指南 | E9: 2015 | F9: 张晓阳 主编 | H9: 原创 | K9: 978-7-5091-7834-8 | L9: 骨科康复总论 | M9: 高 | N9: 未知 | O9: https://lib.zy91.com/opac/book/29400
A10: 9 | B10: 人民军医出版社 | C10: 实用腰椎间盘突出症康复指南 | E10: 2012 | F10: 黄国付 主编 | H10: 原创 | K10: 978-7-5091-5879-1 | L10: 脊柱 | M10: 中 | N10: 未知 | O10: https://lib.zy91.com/opac/book/26788
A11: 10 | B11: 人民军医出版社 | C11: 常见骨伤康复运动与评定 | E11: 2011 | F11: 李小六 主编 | H11: 原创 | K11: 978-7-5091-4792-4 | L11: 评定 | M11: 中 | N11: 未知 | O11: https://lib.zy91.com/opac/book/26206
A12: 11 | B12: 人民军医出版社 | C12: 康复医学前沿 | E12: 2014 | F12: 燕铁斌 主编 | H12: 原创 | K12: 978-7-5091-7251-3 | L12: 其他 | M12: 低 | N12: 未知 | O12: https://lib.zy91.com/opac/book/30423
A13: 12 | B13: 人民邮电出版社 | C13: 运动损伤管理：提升运动表现的损伤预防评估与康复指导 | E13: 2026 | F13: [澳]David Joyce（戴维·乔伊斯），[英]Daniel Lewindon（丹尼尔·莱文德） | H13: 译著 | I13: Sports Injury Prevention and Rehabilitation | J13: Routledge | K13: 978-7-115-54330-1 | L13: 运动康复 | M13: 高 | N13: 未知 | O13: https://www.ptpress.com.cn/shopping/buy?bookId=31528664-bd57-49c7-8391-5de3f931cda2
A14: 13 | B14: 人民邮电出版社 | C14: 基于运动解剖学的功能评估指南：上肢篇 | E14: 2026 | F14: [日]林典雄 | H14: 译著 | K14: 978-7-115-66177-7 | L14: 手与上肢 | M14: 高 | N14: 未知 | O14: http://ptpress.com.cn:8989/book/166177
A15: 14 | B15: 人民邮电出版社 | C15: 肩部康复训练：损伤预防、评估与恢复 | E15: 2025 | H15: 译著（待核） | K15: 978-7-115-61153-6 | L15: 肩肘 | M15: 高 | N15: 未知 | O15: https://opac.bsu.edu.cn/mspace/searchDetailLocal/m2e52c551d693cbe9cd680d0212af8a07
A16: 15 | B16: 人民邮电出版社 | C16: 五十肩功能障碍评估与运动疗法：缓解疼痛 改善挛缩 提升关节功能 | E16: 2025 | F16: [日]赤羽根良和 | H16: 译著 | K16: 978-7-115-66161-6 | L16: 肩肘 | M16: 高 | N16: 未知 | O16: https://www.ptpress.com.cn/shopping/buy?bookId=caa149b2-848c-49c6-af0b-442d0e7af98d
A17: 16 | B17: 人民邮电出版社 | C17: 运动康复训练动作全书：全面提升关节活动度、柔韧性与力量 | E17: 2024 | F17: [英]Elizabeth Bryan（伊丽莎白·布赖恩） | G17: 席蕊 译 | H17: 译著 | I17: The Comprehensive Manual of Therapeutic Exercises: Orthopedic and General Conditions | J17: Slack | K17: 978-7-115-60638-9 | L17: 运动康复 | M17: 高 | N17: 未知 | O17: https://space.nankai.edu.cn/mspace/searchDetailLocal/medd6d915f2983c8d627994cdf78c7f67
A18: 17 | B18: 人民邮电出版社 | C18: 跨越鸿沟：从运动损伤康复到运动表现提升 | E18: 2023 | F18: [美]Sue Falsone（休·法尔索内） | G18: 闫琪，赵鹏 译 | H18: 译著 | I18: Bridging the Gap from Rehab to Performance | J18: On Target Publications | K18: 978-7-115-62828-2 | L18: 运动康复 | M18: 高 | N18: 未知 | O18: https://jglib.gdqy.edu.cn/mspace/searchDetailLocal/md24a27e791fa7cb950776f496e908bca
A19: 18 | B19: 人民邮电出版社 | C19: 运动损伤的评估与康复训练全书（全彩图解版） | E19: 2023 | F19: [英]Maureen Raffensperger（莫琳·拉芬斯珀格） | H19: 译著 | L19: 运动康复 | M19: 高 | N19: 未知 | O19: http://jx.tsxcfw.com/xuekebooks.asp?daima=100216&Page=9
A20: 19 | B20: 人民邮电出版社 | C20: 基于动作分析的专项损伤预防、评估与康复训练 | E20: 2022 | F20: [日]陶山哲夫 主编；[日]赤坂清和 编 | G20: 牟海晶 译 | H20: 译著 | K20: 978-7-115-58191-4 | L20: 运动康复 | M20: 高 | N20: 未知 | O20: https://spacelib.huznu.edu.cn/mspace/searchDetailLocal/m45aa2c165cbbf3130d1a6e310656d50c
A21: 20 | B21: 人民邮电出版社 | C21: 骶髂关节与梨状肌运动功能障碍评估与纠正指南 | E21: 2025 | F21: [英]Paula Clayton（保拉·克莱顿） | H21: 译著 | K21: 978-7-115-58172-3 | L21: 脊柱 | M21: 中 | N21: 未知 | O21: https://www.ptpress.com.cn/shopping/buy?bookId=ae437842-c0f0-4442-9c76-ad5ac8cd076e
A22: 21 | B22: 人民邮电出版社 | C22: 体育运动中的深层组织按摩技术 | E22: 2019 | F22: [英]Jane Johnson（简·约翰逊） | G22: 陈俊飞 译 | H22: 译著 | I22: Deep Tissue Massage | J22: Human Kinetics | K22: 978-7-115-49623-2 | L22: 手法治疗 | M22: 中 | N22: 未知 | O22: https://search-lib.dufe.edu.cn/mspace/searchDetailLocal/me98ad91ac1ecbd4158fedd870553cd24
A23: 22 | B23: 人民邮电出版社 | C23: 人人都能看得懂的运动康复指南（全彩图解版） | E23: 2017 | F23: [西]José Manuel Sanz Mengíbar（何塞·曼努埃尔·桑斯·门希瓦尔） | G23: 董艳艳 译 | H23: 译著 | K23: 978-7-115-45001-2 | L23: 运动康复 | M23: 中 | N23: 未知 | O23: https://jglib.gdqy.edu.cn/mspace/searchDetailLocal/m6aa7e7288b4b26fbfb6e2234d54d7f58
A24: 23 | B24: 人民邮电出版社 | C24: 运动损伤的预防、治疗与恢复 | E24: 2017 | F24: [美]Robert S. Gotlin（罗伯特·S. 高特林）编著 | G24: 高旦潇 译 | H24: 译著 | I24: Sports Injuries Guidebook | J24: Human Kinetics | K24: 978-7-115-45068-5 | L24: 运动康复 | M24: 中 | N24: 未知 | O24: http://60.173.147.75:8081/ILASOPAC/NTRdrBookRetr.do?SearchType=text&SearchKey=7-&LeftSubjectType=subject&LeftSubjectKey=%E8%BF%90%E5%8A%A8%E6%80%A7%E7%96%BE%E7%97%85&leftPublishType=publish&leftPublishKey=%E4%BA%BA%E6%B0%91%E9%82%AE%E7%94%B5%E5%87%BA%E7%89%88%E7%A4%BE
A25: 24 | B25: 人民邮电出版社 | C25: 运动损伤解剖学：康复训练 | E25: 2017 | F25: [英]Leigh Brandon（利·布兰登） | G25: 王震宇，司佳卉 译 | H25: 译著 | I25: Anatomy of Sports Injuries | K25: 978-7-115-46080-6 | L25: 运动康复 | M25: 中 | N25: 未知 | O25: https://www.amazon.com/dp/B074NZKWV9
A26: 25 | B26: 人民邮电出版社 | C26: 羽毛球运动损伤的预防与康复训练（运动损伤预防、评估与康复指导丛书） | E26: 2024 | H26: 原创（待核） | K26: 978-7-115-60290-9 | L26: 运动康复 | M26: 低 | N26: 未知 | O26: https://libnlis.ldu.edu.cn/mspace/searchDetailLocal/m8ead435d59b99eb4ecea61dc425264cf
A27: 26 | B27: 人民邮电出版社 | C27: 精准拉伸：疼痛消除和损伤预防的针对性练习 | E27: 2016 | F27: [美]克里斯蒂安·博格 | G27: 王雄，杨斌 译 | H27: 译著 | L27: 其他 | M27: 低 | N27: 未知 | O27: https://book.douban.com/subject/26818259/
A28: 27 | B28: 化学工业出版社 | C28: 骨科常用护理与康复技术 | E28: 2023 | F28: 张玉梅, 唐永利, 陈小华 主编 | H28: 原创 | K28: 978-7-122-43362-6 | L28: 骨科康复总论 | M28: 中 | N28: 未知 | O28: https://lib.zy91.com/opac/book/38442
A29: 28 | B29: 化学工业出版社 | C29: 体育保健与运动康复技术 | E29: 2016 | F29: 牛映雪, 鹿国晖, 刘杨 主编 | H29: 原创 | K29: 978-7-122-26208-0 | L29: 运动康复 | M29: 低 | N29: 未知 | O29: https://opac.bsu.edu.cn/mspace/searchDetailLocal/m3c468b5ceba00c5a3c5c79665f679148
A30: 29 | B30: 北京体育大学出版社 | C30: 运动康复评定学（高等教育运动医学&运动康复精品教材） | E30: 2021 | F30: 钱菁华 主编 | H30: 原创 | K30: 978-7-5644-3244-7 | L30: 评定 | M30: 高 | N30: 未知 | O30: https://libnlis.ldu.edu.cn/mspace/searchDetailLocal/m5608883e872e141530e392ebc429365a
A31: 30 | B31: 北京体育大学出版社 | C31: 运动康复技术 | E31: 2016 | F31: 《运动康复技术》编写组 编；王安利 主编，钱菁华 副主编 | H31: 原创 | K31: 978-7-5644-2111-3 | L31: 运动康复 | M31: 高 | N31: 未知 | O31: https://libopac.lnpu.edu.cn/mspace/searchDetailLocal/m3bfba6c0f24b31a9a63b57ad6bb22c4b
A32: 31 | B32: 北京体育大学出版社 | C32: 运动康复治疗 | E32: 2016 | F32: 钱菁华 主编 | H32: 原创 | K32: 978-7-5644-2489-3 | L32: 运动康复 | M32: 高 | N32: 未知 | O32: https://opac.bsu.edu.cn/mspace/searchDetailLocal/m5ef9c8e34037c65e4343f64e3b596a5a
A33: 32 | B33: 北京体育大学出版社 | C33: 运动损伤的治疗与康复 | D33: 第2版 | E33: 2016 | F33: 黄涛 主编 | H33: 原创 | K33: 978-7-5644-0421-5 | L33: 运动康复 | M33: 高 | N33: 未知 | O33: https://opac.bsu.edu.cn/mspace/searchDetailLocal/ma21df6b813762c1d08fc72050827037c
A34: 33 | B34: 北京体育大学出版社 | C34: 临床康复学（运动康复专业用教材） | E34: 2017 | F34: 刘华，荣湘江，周华 编 | H34: 原创 | L34: 骨科康复总论 | M34: 中 | N34: 未知 | O34: https://book.douban.com/subject/27048042/
A35: 34 | B35: 北京体育大学出版社 | C35: 运动康复中的有效功能训练 | E35: 2011 | F35: [美]Todd Ellenbecker（托德·艾伦贝克），Mark De Carlo（马克·德卡），Carl DeRosa（卡尔·德罗莎） | G35: 王安利 等译 | H35: 译著 | I35: Effective Functional Progressions in Sport Rehabilitation | J35: Human Kinetics | L35: 运动康复 | M35: 中 | N35: 未知 | O35: https://book.douban.com/subject/7059002/
A36: 35 | B36: 北京大学医学出版社 | C36: 运动医学与运动防护的康复技术 | D36: 第7版 | E36: 2025 | F36: (美) William E. Prentice 原著（原著者推定） | G36: 倪国新 主译 | H36: 译著 | I36: Rehabilitation Techniques for Sports Medicine and Athletic Training (7th ed.) | J36: SLACK | K36: 978-7-5659-3244-1 | L36: 运动康复 | M36: 高 | N36: 未知 | O36: https://bynews.bjmu.edu.cn/zhxw/2025/5d51527066944dbca2390f5c748fc0d6.htm
A37: 36 | B37: 北京大学医学出版社 | C37: 髋膝关节手术及康复500问 | E37: 2024 | F37: 柳剑, 黄野, 王现海 主编 | H37: 原创 | K37: 978-7-5659-2642-6 | L37: 关节置换 | M37: 高 | N37: 未知 | O37: https://lib.zy91.com/opac/book/38464
A38: 37 | B38: 北京大学医学出版社 | C38: 康复医学临床手册 | E38: 2019 | F38: (美) Kimberly A. Sackheim 原著 | G38: 周谋望 主译 | H38: 译著 | I38: Rehab Clinical Pocket Guide: Rehabilitation Medicine | J38: Springer | K38: 978-7-5659-1912-1 | L38: 骨科康复总论 | M38: 中 | N38: 未知 | O38: https://baike.baidu.com/item/%E5%BA%B7%E5%A4%8D%E5%8C%BB%E5%AD%A6%E4%B8%B4%E5%BA%8A%E6%89%8B%E5%86%8C/59743126
A39: 38 | B39: 北京大学医学出版社 | C39: 常见运动创伤的护理和康复 | E39: 2006 | F39: 于长隆 主编 | H39: 原创 | K39: 7-81071-935-1 | L39: 运动康复 | M39: 中 | N39: 未知 | O39: https://lib.zy91.com/opac/book/19046
A40: 39 | B40: 北京科学技术出版社 | C40: 治疗性运动：基础与技术 | D40: 第7版 | E40: 2022 | F40: (美) Carolyn Kisner, Lynn Allen Colby, John Borstad 著 | H40: 译著 | I40: Therapeutic Exercise: Foundations and Techniques (7th ed.) | J40: F.A. Davis | K40: 978-7-5714-2248-6 | L40: 运动康复 | M40: 高 | N40: 未知 | O40: https://m.douban.com/book/subject/36278290/
...

Sheet 出版社统计
A1: 骨科康复相关图书：Springer 以外出版社汇总（检索日期 2026-10-08）
A2: 注1：英文部分为 Elsevier、Wolters Kluwer/LWW、Thieme、Human Kinetics、SLACK、F.A. Davis、Jaypee、McGraw Hill、Wiley、Taylor & Francis、OUP、CUP、Springer Publishing 等出版社的代表性图书，以官网或可靠书目核实，非穷尽清单。
A3: 注2：中文部分已排除前一份表中出现过的出版社（人卫、辽宁科技、中国科技、上海科技、天津科翻、世图、电子工业、湖南科技、山东科技），以高校图书馆书目、当当、豆瓣等核实。
A4: 注3：主题分类和相关度为人工判断；“电子版/在线资源”栏仅记录检索中能确认的信息，空白表示未查到。
A6: 英文：按出版社
A7: 类别 | B7: 数量
A8: Cambridge University Press | B8: =COUNTIF(英文出版社!$B$2:$B$136,A8) -> 1
A9: Elsevier | B9: =COUNTIF(英文出版社!$B$2:$B$136,A9) -> 30
A10: F.A. Davis | B10: =COUNTIF(英文出版社!$B$2:$B$136,A10) -> 7
A11: Human Kinetics | B11: =COUNTIF(英文出版社!$B$2:$B$136,A11) -> 13
A12: Jaypee Brothers Medical Publishers | B12: =COUNTIF(英文出版社!$B$2:$B$136,A12) -> 5
A13: McGraw Hill | B13: =COUNTIF(英文出版社!$B$2:$B$136,A13) -> 6
A14: Oxford University Press | B14: =COUNTIF(英文出版社!$B$2:$B$136,A14) -> 7
A15: SLACK Incorporated | B15: =COUNTIF(英文出版社!$B$2:$B$136,A15) -> 5
A16: Springer Publishing Company | B16: =COUNTIF(英文出版社!$B$2:$B$136,A16) -> 5
A17: Taylor & Francis | B17: =COUNTIF(英文出版社!$B$2:$B$136,A17) -> 13
A18: Thieme | B18: =COUNTIF(英文出版社!$B$2:$B$136,A18) -> 17
A19: Wiley | B19: =COUNTIF(英文出版社!$B$2:$B$136,A19) -> 6
A20: Wolters Kluwer | B20: =COUNTIF(英文出版社!$B$2:$B$136,A20) -> 20
A21: 合计 | B21: =SUM(B8:B20) -> 135
A23: 英文：按相关度
A24: 类别 | B24: 数量
A25: 高 | B25: =COUNTIF(英文出版社!$O$2:$O$136,A25) -> 72
A26: 中 | B26: =COUNTIF(英文出版社!$O$2:$O$136,A26) -> 53
A27: 低 | B27: =COUNTIF(英文出版社!$O$2:$O$136,A27) -> 10
A28: 合计 | B28: =SUM(B25:B27) -> 135
A30: 中文：按出版社
A31: 类别 | B31: 数量
A32: 上海交通大学出版社 | B32: =COUNTIF(中文出版社!$B$2:$B$64,A32) -> 1
A33: 中国协和医科大学出版社 | B33: =COUNTIF(中文出版社!$B$2:$B$64,A33) -> 2
A34: 人民体育出版社 | B34: =COUNTIF(中文出版社!$B$2:$B$64,A34) -> 3
A35: 人民军医出版社 | B35: =COUNTIF(中文出版社!$B$2:$B$64,A35) -> 5
A36: 人民邮电出版社 | B36: =COUNTIF(中文出版社!$B$2:$B$64,A36) -> 15
A37: 化学工业出版社 | B37: =COUNTIF(中文出版社!$B$2:$B$64,A37) -> 2
A38: 北京体育大学出版社 | B38: =COUNTIF(中文出版社!$B$2:$B$64,A38) -> 6
A39: 北京大学医学出版社 | B39: =COUNTIF(中文出版社!$B$2:$B$64,A39) -> 4
A40: 北京科学技术出版社 | B40: =COUNTIF(中文出版社!$B$2:$B$64,A40) -> 8
A41: 华夏出版社 | B41: =COUNTIF(中文出版社!$B$2:$B$64,A41) -> 2
A42: 厦门大学出版社 | B42: =COUNTIF(中文出版社!$B$2:$B$64,A42) -> 1
A43: 广东科技出版社 | B43: =COUNTIF(中文出版社!$B$2:$B$64,A43) -> 1
...
